## 1、<span style="color:brown">多个异常使用捕获，怎么处理？</span>

**1.1、处理方式：**

1. 多个异常分别处理；

2. 多个异常一次捕获，多次处理；

   <u>如果异常存在子父类关系，那么子类必须在上面！！</u>

   ```java
   ArrayIndexOutOfBoundsException extends IndexOutOfBoundsException
   ```

3. 多个异常一次捕获，一次处理；

**1.2、范例：**

<u>*多个异常分别处理*</u>：

```java
public class Demo04 {
    public static void main(String[] args) {
        try{
            int[] a = {1,2,3};
            System.out.println(a[3]);//ArrayIndexOutOfBoundsException
        }catch(ArrayIndexOutOfBoundsException e){
            System.out.println(e);
        }
        try {
            List<Integer> list = new ArrayList<>();
            Collections.addAll(list,4,5,6);
            System.out.println(list.get(3));//IndexOutOfBoundsException
        }catch (IndexOutOfBoundsException e){
            System.out.println(e);
        }
    }
}
```

```apl
java.lang.ArrayIndexOutOfBoundsException: 3
java.lang.IndexOutOfBoundsException: Index: 3, Size: 3
```

<u>*多个异常一次捕获，多次处理*</u>：

```java
public class Demo04 {
    public static void main(String[] args) {
        try{
            /**
             * 由于此时数组和集合都存在异常，但是
             *      数组的异常最先被捕获，从而最终导致JVM中断程序
             *   因此，集合异常无法捕获，并打印在控制台
             */
            int[] a = {1,2,3};
            System.out.println(a[3]);//ArrayIndexOutOfBoundsException

            List<Integer> list = new ArrayList<>();
            Collections.addAll(list,4,5,6);
            System.out.println(list.get(3));//IndexOutOfBoundsException
        }catch(ArrayIndexOutOfBoundsException e){
            System.out.println(e);
        }catch (IndexOutOfBoundsException e){
            System.out.println(e);
        }
    }
}
```

```apl
java.lang.ArrayIndexOutOfBoundsException: 3
```

<u>*多个异常一次捕获，一次处理*</u>：

```java
public class Demo04 {
    public static void main(String[] args) {
        try{
            int[] a = {1,2,3};
            System.out.println(a[3]);//ArrayIndexOutOfBoundsException

            List<Integer> list = new ArrayList<>();
            Collections.addAll(list,4,5,6);
            System.out.println(list.get(3));//IndexOutOfBoundsException
        }catch(Exception e){
            /**
             * 由于ArrayIndexOutOfBoundsException extends IndexOutOfBoundsException
             * 在try---catch中，如果异常存在子父类关系，子类必须写在上面
             *      而在”多个异常一次捕获，一次处理中“，catch部分只需要处理父类异常即可！！
             		或者直接  Exception e,这样涵盖了所有的异常
             */
            System.out.println(e);
        }
    }
}
```

```apl
java.lang.ArrayIndexOutOfBoundsException: 3
```



## 2、<span style="color:brown">try--catch--finally的执行顺序：</span>

## 对于List集合等引用类型，在对象里存的不是变量本身，而是变量的地址，所以当finally通过地址改变了变量，还是会影响方法返回值的。

**2.1、总结：**

***1、不管有没有出现异常，finally块中代码都会执行；***
***2、当try和catch中有return时，finally仍然会执行；***
***3、finally是在return后面的表达式运算后执行的（此时并没有返回运算后的值，而是先把要返回的值保存起来，不管finally中的代码怎么样，返回的值都不会改变，任然是之前保存的值），所以函数返回值是在finally执行前确定的；***
***4、finally中最好不要包含return，否则程序会提前退出，返回值不是try或catch中保存的返回值。***

**2.2、分析：**

````java
//无return，无异常
try ---> finally
````

```java
//无return，有异常
try(未出现异常的前半段) ---> catch ---> finally
```

```java
//try中有return，无异常
try ---> finally ---> return(try)

//catch中有return，无异常
try ---> finally
```

```java
//try或者catch中有return，有异常
try(未出现异常的前半段) ---> catch ---> finally ---> return(catch)
```

```java
//只要finally中有return，不管是否存在异常，catch和try中是否有return
try/catch ---> return(finally)
```



## 3、<span style="color:brown">异常的子父类关系解析：</span>

![解释](https://raw.githubusercontent.com/root-bine/image/main/Typora-image/%E5%AD%90%E7%88%B6%E7%B1%BB%E5%BC%82%E5%B8%B8%E8%A7%A3%E9%87%8A.png)

<img src="https://raw.githubusercontent.com/root-bine/image/main/Typora-image/%E7%88%B6%E7%B1%BB%E4%BB%A3%E7%A0%81.png" alt="父类" style="zoom:67%;" />

<img src="https://raw.githubusercontent.com/root-bine/image/main/Typora-image/%E5%AD%90%E7%B1%BB%E4%BB%A3%E7%A0%81.png" alt="子类" style="zoom:67%;" />